Now when @pytest.fixture is being applied to the same function ValueError is raised.