With usage errors ``exitstatus`` is set to ``EXIT_USAGEERROR`` in the ``pytest_sessionfinish`` hook now as expected.
